<?xml version="1.0"?>
<robot xmlns:sensor="http://playerstage.sourceforge.net/gazebo/xmlschema/#sensor" xmlns:controller="http://playerstage.sourceforge.net/gazebo/xmlschema/#controller"
  xmlns:interface="http://playerstage.sourceforge.net/gazebo/xmlschema/#interface" xmlns:xacro="http://ros.org/wiki/xacro"
  name="schunk_pg70">

  <xacro:property name="robot_prefix" value="schunk/" />


  <link name="${robot_prefix}schunk_pg70_base">
  </link>

  <link name="${robot_prefix}schunk_pg70_finger1">
  </link>

  <joint name="${robot_prefix}pg70_finger1_joint" type="prismatic">
    <axis xyz="0 0 1" />
    <parent link="${robot_prefix}schunk_pg70_base" />
    <child link="${robot_prefix}schunk_pg70_finger1" />
    <origin xyz="0 0 0" rpy="0 0 0" />
  </joint>

  <link name="${robot_prefix}schunk_pg70_finger2">
  </link>

  <joint name="${robot_prefix}pg70_finger2_joint" type="prismatic">
    <axis xyz="0 0 1" />
    <parent link="${robot_prefix}schunk_pg70_base" />
    <child link="${robot_prefix}schunk_pg70_finger2" />
    <origin xyz="0 0 0" rpy="0 0 0" />
  </joint>


</robot>