<?xml version="1.0"?>
<robot xmlns:sensor="http://playerstage.sourceforge.net/gazebo/xmlschema/#sensor" xmlns:controller="http://playerstage.sourceforge.net/gazebo/xmlschema/#controller"
  xmlns:interface="http://playerstage.sourceforge.net/gazebo/xmlschema/#interface" xmlns:xacro="http://www.ros.org/wiki/xacro"
  name="grasshopper">
<!--xacro:macro name="grasshopper" params="robot_prefix parent_link"-->

  <xacro:property name="robot_prefix" value="grasshopper/" />
  <xacro:property name="parent_link" value="bonmetc60/link6" />
 
 <link name="${parent_link}">
  </link>

  <link name="${robot_prefix}base_link">
  </link>

  <joint name="${robot_prefix}fixing_link" type="fixed">
    <parent link="${parent_link}" />
    <child link="${robot_prefix}base_link" />
    <origin xyz="0 0 0" rpy="0 0 0" />
    <!--<limit effort="1000" velocity="1000" lower="-2.9670" upper="2.9670" />-->
  </joint>

  <link name="${robot_prefix}link1">
  </link>

  <joint name="${robot_prefix}joint1" type="prismatic">
    <axis xyz="0 0 1" />
    <parent link="${robot_prefix}base_link" />
    <child link="${robot_prefix}link1" />
    <origin xyz="0 0 0.20" rpy="3.14 0 0" />
    <limit effort="1000" velocity="1000" lower="-2.9670" upper="2.9670" />
  </joint>

  <link name="${robot_prefix}link2">
  </link>

  <joint name="${robot_prefix}joint2" type="prismatic">
    <axis xyz="0 0 1" />
    <parent link="${robot_prefix}link1" />
    <child link="${robot_prefix}link2" />
    <origin xyz="0 0 -0.1" rpy="1.57 0 0" />
    <limit effort="1000" velocity="1000" lower="-2.9670" upper="2.9670" />
  </joint>

  <link name="${robot_prefix}finger_r">
  </link>

  <joint name="${robot_prefix}joint3" type="prismatic">
    <axis xyz="0 0 1" />
    <parent link="${robot_prefix}link2" />
    <child link="${robot_prefix}finger_r" />
    <origin xyz="0 -0.092 -0.0491" rpy="0 1.57 0" />
    <limit effort="1000" velocity="1000" lower="-2.9670" upper="2.9670" />
  </joint>

  <link name="${robot_prefix}finger_l">
  </link>

  <joint name="${robot_prefix}joint4" type="prismatic">
    <axis xyz="0 0 1" />
    <parent link="${robot_prefix}link2" />
    <child link="${robot_prefix}finger_l" />
    <origin xyz="0 -0.092 -0.0491" rpy="0 1.57 0" />
    <limit effort="1000" velocity="1000" lower="-2.9670" upper="2.9670" />-
  </joint>

  <link name="${robot_prefix}centerpoint">
  </link>

  <joint name="${robot_prefix}link2_to_centerpoint" type="fixed">
    <parent link="${robot_prefix}link2" />
    <child link="${robot_prefix}centerpoint" />
    <origin xyz="0 -0.092 -0.0491" rpy="3.14 0 0" />
  </joint>

  <link name="${robot_prefix}driver">
  </link>

  <joint name="${robot_prefix}base_to_driver" type="fixed">
    <parent link="${robot_prefix}base_link" />
    <child link="${robot_prefix}driver" />
    <origin xyz="0 -0.0741 0.37" rpy="0 0 3.14" />
  </joint>

<!--/xacro:macro-->
</robot>