<?xml version="1.0"?>
<robot xmlns:sensor="http://playerstage.sourceforge.net/gazebo/xmlschema/#sensor" xmlns:controller="http://playerstage.sourceforge.net/gazebo/xmlschema/#controller"
  xmlns:interface="http://playerstage.sourceforge.net/gazebo/xmlschema/#interface" xmlns:xacro="http://ros.org/wiki/xacro"
  name="bonmetc60">
<!--xacro:macro name="bonmetc60" params="prefix"-->
  <xacro:property name="robot_prefix" value="bonmetc60/" />


  <link name="${robot_prefix}base_link">
  </link>

  <link name="${robot_prefix}link1">
  </link>

  <joint name="${robot_prefix}joint_1" type="continuous">
    <axis xyz="0 0 1" />
    <parent link="${robot_prefix}base_link" />
    <child link="${robot_prefix}link1" />
    <origin xyz="0.00 0 0.32" rpy="0 0 0" />
    <limit effort="1000" velocity="1000" lower="-2.9670" upper="2.9670" /> <!-- TODO -->
    <!-- -170,+170 -->
  </joint>

  <link name="${robot_prefix}link2">
  </link>

  <joint name="${robot_prefix}joint_2" type="continuous">
    <axis xyz="0 0 1" />
    <parent link="${robot_prefix}link1" />
    <child link="${robot_prefix}link2" />
    <origin xyz="0.05 0 0.0" rpy="1.571 0 0" />
    <limit effort="1000" velocity="1000" lower="-2.267" upper="1.57" />  <!-- TODO -->
    <!-- -85,+155 -->
  </joint>

  <link name="${robot_prefix}link3">
  </link>

  <joint name="${robot_prefix}joint_3" type="continuous">
    <axis xyz="0 0 1" />
    <parent link="${robot_prefix}link2" />
    <child link="${robot_prefix}link3" />
    <origin xyz="0 0.27 0" rpy="0 0 0" />
    <limit effort="1000" velocity="1000" lower="-1.22" upper="1.483" />  <!-- TODO -->
    <!-- -170,+0 -->
  </joint>

  <link name="${robot_prefix}link4">
  </link>

  <joint name="${robot_prefix}joint_4" type="continuous">
    <axis xyz="0 0 1" />
    <parent link="${robot_prefix}link3" />
    <child link="${robot_prefix}link4" />
    <!-- <origin xyz="0.299 0.07 0.0" rpy="0 1.571 0" /> -->
    <origin xyz="0.299 0.07 0.0" rpy="0 1.571 0" />
    <limit effort="1000" velocity="1000" lower="-2.967" upper="2.967" />  <!-- TODO -->
  </joint>

  <link name="${robot_prefix}link5">
  </link>

  <joint name="${robot_prefix}joint_5" type="continuous">
    <axis xyz="0 0 1" />
    <parent link="${robot_prefix}link4" />
    <child link="${robot_prefix}link5" />
    <origin xyz="0.0 0.0 0.0" rpy="0.0 -1.57 0.0" />
    <limit effort="1000" velocity="1000" lower="-1.74" upper="1.74" />  <!-- TODO -->
    <!-- -130,+130 -->
  </joint>

  <link name="${robot_prefix}link6">
  </link>

  <joint name="${robot_prefix}joint_6" type="continuous">
    <axis xyz="0 0 1" />
    <parent link="${robot_prefix}link5" />
    <child link="${robot_prefix}link6" />
    <origin xyz="0.0785 0 0.0" rpy="0 1.57 0" />
    <limit effort="1000" velocity="1000" lower="-6.28" upper="6.28" />  <!-- TODO -->
  </joint>

  <!--
  <link name="${robot_prefix}tool">
  </link>

  <joint name="${robot_prefix}link6_to_tool" type="continuous">
    <axis xyz="0 0 1" />
    <parent link="${robot_prefix}link6" />
    <child link="${robot_prefix}tool" />
    <origin xyz="0 0 -0.085" rpy="0 0 0" />
  </joint>
-->
<!--/xacro:macro-->
</robot>
